using System;
using System.Linq;
using System.Threading.Tasks;
using Functional.Models.Enums;
using Functional.Models.Implementations.Result;
using Functional.Models.Interfaces.Result;
using FunctionalXUnit.Data;
using FunctionalXUnit.Mocks.Implementation;
using Xunit;
using static Functional.FunctionalExtensions.Async.ResultExtension.ResultValue.ResultValueTryAsyncExtensions;
using static FunctionalXUnit.Data.ErrorData;

namespace FunctionalXUnit.FunctionalExtensions.Async.ResultExtension.ResultValue
{
    /// <summary>
    /// Методы расширения для результирующего ответа со значением и обработкой исключений асинхронно. Тесты
    /// </summary>
    public class ResultValueTryAsyncExtensionsTest
    {
        /// <summary>
        /// Обработать асинхронную функцию, вернуть результирующий ответ со значением
        /// </summary>
        [Fact]
        public async Task ResultValueTryAsync_Ok()
        {
            var resultValue = await ResultValueTryAsync(() => AsyncFunctions.DivisionAsync(1), Exceptions.ExceptionError());

            Assert.True(resultValue.OkStatus);
            Assert.Equal(await AsyncFunctions.DivisionAsync(1), resultValue.Value);
        }

        /// <summary>
        /// Обработать асинхронную функцию, вернуть результирующий ответ с ошибкой
        /// </summary>
        [Fact]
        public async Task ResultValueTryAsync_Exception()
        {
            var resultValue = await ResultValueTryAsync(() => AsyncFunctions.DivisionAsync(0), Exceptions.ExceptionError());

            Assert.True(resultValue.HasErrors);
            Assert.Equal(ErrorResultType.DevideByZero, resultValue.Errors.First().ErrorResultType);
        }

        /// <summary>
        /// Положительный результирующий ответ и отсутствие исключения
        /// </summary>
        [Fact]
        public async Task ResultValueTryOkAsync_OkResult_OkTry()
        {
            const int initialNumber = 2;
            var numberResult = new ResultValue<int>(initialNumber);

            var numberAfterTry = await numberResult.ResultValueTryOkAsync(AsyncFunctions.DivisionAsync, CreateErrorTest());

            Assert.True(numberAfterTry.OkStatus);
            Assert.Equal(await AsyncFunctions.DivisionAsync(initialNumber), numberAfterTry.Value);
        }

        /// <summary>
        /// Результирующий ответ с ошибкой и отсутствие исключения
        /// </summary>
        [Fact]
        public async Task ResultValueTryOkAsync_ErrorResult_OkTry()
        {
            var initialError = CreateErrorTest();
            var numberResult = new ResultValue<int>(initialError);

            var numberAfterTry = await numberResult.ResultValueTryOkAsync(AsyncFunctions.DivisionAsync, CreateErrorTest());

            Assert.True(numberAfterTry.HasErrors);
            Assert.True(initialError.Equals(numberAfterTry.Errors.First()));
        }

        /// <summary>
        /// Положительный результирующий ответ и исключение
        /// </summary>
        [Fact]
        public async Task ResultValueTryOkAsync_OkResult_ExceptionTry()
        {
            const int initialNumber = 0;
            var numberResult = new ResultValue<int>(initialNumber);

            var numberAfterTry = await numberResult.ResultValueTryOkAsync(AsyncFunctions.DivisionAsync, Exceptions.ExceptionError());

            Assert.True(numberAfterTry.HasErrors);
            Assert.Equal(ErrorResultType.DevideByZero, numberAfterTry.Errors.First().ErrorResultType);
        }

        /// <summary>
        /// Результирующий ответ с ошибкой и исключение
        /// </summary>
        [Fact]
        public async Task ResultValueTryOkAsync_ErrorResult_ExceptionTry()
        {
            var initialError = CreateErrorTest();
            var numberResult = new ResultValue<int>(initialError);

            var numberAfterTry = await numberResult.ResultValueTryOkAsync(AsyncFunctions.DivisionAsync, Exceptions.ExceptionError());

            Assert.True(numberAfterTry.HasErrors);
            Assert.True(initialError.Equals(numberAfterTry.Errors.First()));
        }
    }
}